2019-04-14 12:27:54,039 ERROR: Exception on /reset_pass [POST] [in /home/weiss/CODES/BM/intent_gatherer/intent_gatherer_venv/lib/python3.7/site-packages/flask/app.py:1761]
Traceback (most recent call last):
  File "/home/weiss/CODES/BM/intent_gatherer/intent_gatherer_venv/lib/python3.7/site-packages/flask/app.py", line 2292, in wsgi_app
    response = self.full_dispatch_request()
  File "/home/weiss/CODES/BM/intent_gatherer/intent_gatherer_venv/lib/python3.7/site-packages/flask/app.py", line 1815, in full_dispatch_request
    rv = self.handle_user_exception(e)
  File "/home/weiss/CODES/BM/intent_gatherer/intent_gatherer_venv/lib/python3.7/site-packages/flask/app.py", line 1718, in handle_user_exception
    reraise(exc_type, exc_value, tb)
  File "/home/weiss/CODES/BM/intent_gatherer/intent_gatherer_venv/lib/python3.7/site-packages/flask/_compat.py", line 35, in reraise
    raise value
  File "/home/weiss/CODES/BM/intent_gatherer/intent_gatherer_venv/lib/python3.7/site-packages/flask/app.py", line 1813, in full_dispatch_request
    rv = self.dispatch_request()
  File "/home/weiss/CODES/BM/intent_gatherer/intent_gatherer_venv/lib/python3.7/site-packages/flask/app.py", line 1799, in dispatch_request
    return self.view_functions[rule.endpoint](**req.view_args)
  File "/home/weiss/CODES/BM/intent_gatherer/flask_backend/app/routes.py", line 145, in reset_password
    send_password_reset_email(user)
  File "/home/weiss/CODES/BM/intent_gatherer/flask_backend/app/email.py", line 17, in send_password_reset_email
    text_body=render_template('reset_pass_mail_text.txt',user=user,token=token))
  File "/home/weiss/CODES/BM/intent_gatherer/flask_backend/app/email.py", line 8, in send_mail
    mail.send(message)
  File "/home/weiss/CODES/BM/intent_gatherer/intent_gatherer_venv/lib/python3.7/site-packages/flask_mail.py", line 491, in send
    with self.connect() as connection:
  File "/home/weiss/CODES/BM/intent_gatherer/intent_gatherer_venv/lib/python3.7/site-packages/flask_mail.py", line 144, in __enter__
    self.host = self.configure_host()
  File "/home/weiss/CODES/BM/intent_gatherer/intent_gatherer_venv/lib/python3.7/site-packages/flask_mail.py", line 165, in configure_host
    host.login(self.mail.username, self.mail.password)
  File "/home/weiss/miniconda3/lib/python3.7/smtplib.py", line 730, in login
    raise last_exception
  File "/home/weiss/miniconda3/lib/python3.7/smtplib.py", line 721, in login
    initial_response_ok=initial_response_ok)
  File "/home/weiss/miniconda3/lib/python3.7/smtplib.py", line 642, in auth
    raise SMTPAuthenticationError(code, resp)
smtplib.SMTPAuthenticationError: (534, b'5.7.9 Application-specific password required. Learn more at\n5.7.9  https://support.google.com/mail/?p=InvalidSecondFactor x192sm17248122wmf.48 - gsmtp')
2019-04-14 12:27:54,046 ERROR: Internal error, please wait until the maintainers fix the issue [in /home/weiss/CODES/BM/intent_gatherer/flask_backend/app/errors.py:13]
2019-04-14 12:31:18,693 INFO: The application started [in /home/weiss/CODES/BM/intent_gatherer/flask_backend/app/__init__.py:44]
2019-04-14 12:31:23,299 ERROR: Exception on /reset_pass [POST] [in /home/weiss/CODES/BM/intent_gatherer/intent_gatherer_venv/lib/python3.7/site-packages/flask/app.py:1761]
Traceback (most recent call last):
  File "/home/weiss/CODES/BM/intent_gatherer/intent_gatherer_venv/lib/python3.7/site-packages/flask/app.py", line 2292, in wsgi_app
    response = self.full_dispatch_request()
  File "/home/weiss/CODES/BM/intent_gatherer/intent_gatherer_venv/lib/python3.7/site-packages/flask/app.py", line 1815, in full_dispatch_request
    rv = self.handle_user_exception(e)
  File "/home/weiss/CODES/BM/intent_gatherer/intent_gatherer_venv/lib/python3.7/site-packages/flask/app.py", line 1718, in handle_user_exception
    reraise(exc_type, exc_value, tb)
  File "/home/weiss/CODES/BM/intent_gatherer/intent_gatherer_venv/lib/python3.7/site-packages/flask/_compat.py", line 35, in reraise
    raise value
  File "/home/weiss/CODES/BM/intent_gatherer/intent_gatherer_venv/lib/python3.7/site-packages/flask/app.py", line 1813, in full_dispatch_request
    rv = self.dispatch_request()
  File "/home/weiss/CODES/BM/intent_gatherer/intent_gatherer_venv/lib/python3.7/site-packages/flask/app.py", line 1799, in dispatch_request
    return self.view_functions[rule.endpoint](**req.view_args)
  File "/home/weiss/CODES/BM/intent_gatherer/flask_backend/app/routes.py", line 145, in reset_password
    send_password_reset_email(user)
  File "/home/weiss/CODES/BM/intent_gatherer/flask_backend/app/email.py", line 17, in send_password_reset_email
    text_body=render_template('reset_pass_mail_text.txt',user=user,token=token))
  File "/home/weiss/CODES/BM/intent_gatherer/flask_backend/app/email.py", line 8, in send_mail
    mail.send(message)
  File "/home/weiss/CODES/BM/intent_gatherer/intent_gatherer_venv/lib/python3.7/site-packages/flask_mail.py", line 491, in send
    with self.connect() as connection:
  File "/home/weiss/CODES/BM/intent_gatherer/intent_gatherer_venv/lib/python3.7/site-packages/flask_mail.py", line 144, in __enter__
    self.host = self.configure_host()
  File "/home/weiss/CODES/BM/intent_gatherer/intent_gatherer_venv/lib/python3.7/site-packages/flask_mail.py", line 165, in configure_host
    host.login(self.mail.username, self.mail.password)
  File "/home/weiss/miniconda3/lib/python3.7/smtplib.py", line 730, in login
    raise last_exception
  File "/home/weiss/miniconda3/lib/python3.7/smtplib.py", line 721, in login
    initial_response_ok=initial_response_ok)
  File "/home/weiss/miniconda3/lib/python3.7/smtplib.py", line 642, in auth
    raise SMTPAuthenticationError(code, resp)
smtplib.SMTPAuthenticationError: (534, b'5.7.9 Application-specific password required. Learn more at\n5.7.9  https://support.google.com/mail/?p=InvalidSecondFactor a126sm12788626wmh.4 - gsmtp')
2019-04-14 12:31:23,303 ERROR: Internal error, please wait until the maintainers fix the issue [in /home/weiss/CODES/BM/intent_gatherer/flask_backend/app/errors.py:13]
2019-04-14 12:31:37,772 INFO: The application started [in /home/weiss/CODES/BM/intent_gatherer/flask_backend/app/__init__.py:44]
2019-04-14 12:31:45,875 ERROR: Exception on /reset_pass [POST] [in /home/weiss/CODES/BM/intent_gatherer/intent_gatherer_venv/lib/python3.7/site-packages/flask/app.py:1761]
Traceback (most recent call last):
  File "/home/weiss/CODES/BM/intent_gatherer/intent_gatherer_venv/lib/python3.7/site-packages/flask/app.py", line 2292, in wsgi_app
    response = self.full_dispatch_request()
  File "/home/weiss/CODES/BM/intent_gatherer/intent_gatherer_venv/lib/python3.7/site-packages/flask/app.py", line 1815, in full_dispatch_request
    rv = self.handle_user_exception(e)
  File "/home/weiss/CODES/BM/intent_gatherer/intent_gatherer_venv/lib/python3.7/site-packages/flask/app.py", line 1718, in handle_user_exception
    reraise(exc_type, exc_value, tb)
  File "/home/weiss/CODES/BM/intent_gatherer/intent_gatherer_venv/lib/python3.7/site-packages/flask/_compat.py", line 35, in reraise
    raise value
  File "/home/weiss/CODES/BM/intent_gatherer/intent_gatherer_venv/lib/python3.7/site-packages/flask/app.py", line 1813, in full_dispatch_request
    rv = self.dispatch_request()
  File "/home/weiss/CODES/BM/intent_gatherer/intent_gatherer_venv/lib/python3.7/site-packages/flask/app.py", line 1799, in dispatch_request
    return self.view_functions[rule.endpoint](**req.view_args)
  File "/home/weiss/CODES/BM/intent_gatherer/flask_backend/app/routes.py", line 145, in reset_password
    send_password_reset_email(user)
  File "/home/weiss/CODES/BM/intent_gatherer/flask_backend/app/email.py", line 17, in send_password_reset_email
    text_body=render_template('reset_pass_mail_text.txt',user=user,token=token))
  File "/home/weiss/CODES/BM/intent_gatherer/flask_backend/app/email.py", line 8, in send_mail
    mail.send(message)
  File "/home/weiss/CODES/BM/intent_gatherer/intent_gatherer_venv/lib/python3.7/site-packages/flask_mail.py", line 491, in send
    with self.connect() as connection:
  File "/home/weiss/CODES/BM/intent_gatherer/intent_gatherer_venv/lib/python3.7/site-packages/flask_mail.py", line 144, in __enter__
    self.host = self.configure_host()
  File "/home/weiss/CODES/BM/intent_gatherer/intent_gatherer_venv/lib/python3.7/site-packages/flask_mail.py", line 165, in configure_host
    host.login(self.mail.username, self.mail.password)
  File "/home/weiss/miniconda3/lib/python3.7/smtplib.py", line 730, in login
    raise last_exception
  File "/home/weiss/miniconda3/lib/python3.7/smtplib.py", line 721, in login
    initial_response_ok=initial_response_ok)
  File "/home/weiss/miniconda3/lib/python3.7/smtplib.py", line 642, in auth
    raise SMTPAuthenticationError(code, resp)
smtplib.SMTPAuthenticationError: (534, b'5.7.9 Application-specific password required. Learn more at\n5.7.9  https://support.google.com/mail/?p=InvalidSecondFactor t24sm17121600wmi.10 - gsmtp')
2019-04-14 12:31:45,881 ERROR: Internal error, please wait until the maintainers fix the issue [in /home/weiss/CODES/BM/intent_gatherer/flask_backend/app/errors.py:13]
2019-04-14 12:36:58,136 INFO: The application started [in /home/weiss/CODES/BM/intent_gatherer/flask_backend/app/__init__.py:44]
2019-04-14 12:37:07,360 ERROR: Exception on /reset_pass [POST] [in /home/weiss/CODES/BM/intent_gatherer/intent_gatherer_venv/lib/python3.7/site-packages/flask/app.py:1761]
Traceback (most recent call last):
  File "/home/weiss/CODES/BM/intent_gatherer/intent_gatherer_venv/lib/python3.7/site-packages/flask/app.py", line 2292, in wsgi_app
    response = self.full_dispatch_request()
  File "/home/weiss/CODES/BM/intent_gatherer/intent_gatherer_venv/lib/python3.7/site-packages/flask/app.py", line 1815, in full_dispatch_request
    rv = self.handle_user_exception(e)
  File "/home/weiss/CODES/BM/intent_gatherer/intent_gatherer_venv/lib/python3.7/site-packages/flask/app.py", line 1718, in handle_user_exception
    reraise(exc_type, exc_value, tb)
  File "/home/weiss/CODES/BM/intent_gatherer/intent_gatherer_venv/lib/python3.7/site-packages/flask/_compat.py", line 35, in reraise
    raise value
  File "/home/weiss/CODES/BM/intent_gatherer/intent_gatherer_venv/lib/python3.7/site-packages/flask/app.py", line 1813, in full_dispatch_request
    rv = self.dispatch_request()
  File "/home/weiss/CODES/BM/intent_gatherer/intent_gatherer_venv/lib/python3.7/site-packages/flask/app.py", line 1799, in dispatch_request
    return self.view_functions[rule.endpoint](**req.view_args)
  File "/home/weiss/CODES/BM/intent_gatherer/flask_backend/app/routes.py", line 145, in reset_password
    send_password_reset_email(user)
  File "/home/weiss/CODES/BM/intent_gatherer/flask_backend/app/email.py", line 17, in send_password_reset_email
    text_body=render_template('reset_pass_mail_text.txt',user=user,token=token))
  File "/home/weiss/CODES/BM/intent_gatherer/flask_backend/app/email.py", line 8, in send_mail
    mail.send(message)
  File "/home/weiss/CODES/BM/intent_gatherer/intent_gatherer_venv/lib/python3.7/site-packages/flask_mail.py", line 491, in send
    with self.connect() as connection:
  File "/home/weiss/CODES/BM/intent_gatherer/intent_gatherer_venv/lib/python3.7/site-packages/flask_mail.py", line 144, in __enter__
    self.host = self.configure_host()
  File "/home/weiss/CODES/BM/intent_gatherer/intent_gatherer_venv/lib/python3.7/site-packages/flask_mail.py", line 165, in configure_host
    host.login(self.mail.username, self.mail.password)
  File "/home/weiss/miniconda3/lib/python3.7/smtplib.py", line 730, in login
    raise last_exception
  File "/home/weiss/miniconda3/lib/python3.7/smtplib.py", line 721, in login
    initial_response_ok=initial_response_ok)
  File "/home/weiss/miniconda3/lib/python3.7/smtplib.py", line 642, in auth
    raise SMTPAuthenticationError(code, resp)
smtplib.SMTPAuthenticationError: (534, b'5.7.9 Application-specific password required. Learn more at\n5.7.9  https://support.google.com/mail/?p=InvalidSecondFactor q17sm38106396wrw.70 - gsmtp')
2019-04-14 12:37:07,365 ERROR: Internal error, please wait until the maintainers fix the issue [in /home/weiss/CODES/BM/intent_gatherer/flask_backend/app/errors.py:13]
2019-04-14 12:37:41,428 INFO: The application started [in /home/weiss/CODES/BM/intent_gatherer/flask_backend/app/__init__.py:44]
2019-04-14 12:37:44,867 ERROR: Exception on /reset_pass [POST] [in /home/weiss/CODES/BM/intent_gatherer/intent_gatherer_venv/lib/python3.7/site-packages/flask/app.py:1761]
Traceback (most recent call last):
  File "/home/weiss/CODES/BM/intent_gatherer/intent_gatherer_venv/lib/python3.7/site-packages/flask/app.py", line 2292, in wsgi_app
    response = self.full_dispatch_request()
  File "/home/weiss/CODES/BM/intent_gatherer/intent_gatherer_venv/lib/python3.7/site-packages/flask/app.py", line 1815, in full_dispatch_request
    rv = self.handle_user_exception(e)
  File "/home/weiss/CODES/BM/intent_gatherer/intent_gatherer_venv/lib/python3.7/site-packages/flask/app.py", line 1718, in handle_user_exception
    reraise(exc_type, exc_value, tb)
  File "/home/weiss/CODES/BM/intent_gatherer/intent_gatherer_venv/lib/python3.7/site-packages/flask/_compat.py", line 35, in reraise
    raise value
  File "/home/weiss/CODES/BM/intent_gatherer/intent_gatherer_venv/lib/python3.7/site-packages/flask/app.py", line 1813, in full_dispatch_request
    rv = self.dispatch_request()
  File "/home/weiss/CODES/BM/intent_gatherer/intent_gatherer_venv/lib/python3.7/site-packages/flask/app.py", line 1799, in dispatch_request
    return self.view_functions[rule.endpoint](**req.view_args)
  File "/home/weiss/CODES/BM/intent_gatherer/flask_backend/app/routes.py", line 145, in reset_password
    send_password_reset_email(user)
  File "/home/weiss/CODES/BM/intent_gatherer/flask_backend/app/email.py", line 17, in send_password_reset_email
    text_body=render_template('reset_pass_mail_text.txt',user=user,token=token))
  File "/home/weiss/CODES/BM/intent_gatherer/flask_backend/app/email.py", line 8, in send_mail
    mail.send(message)
  File "/home/weiss/CODES/BM/intent_gatherer/intent_gatherer_venv/lib/python3.7/site-packages/flask_mail.py", line 491, in send
    with self.connect() as connection:
  File "/home/weiss/CODES/BM/intent_gatherer/intent_gatherer_venv/lib/python3.7/site-packages/flask_mail.py", line 144, in __enter__
    self.host = self.configure_host()
  File "/home/weiss/CODES/BM/intent_gatherer/intent_gatherer_venv/lib/python3.7/site-packages/flask_mail.py", line 165, in configure_host
    host.login(self.mail.username, self.mail.password)
  File "/home/weiss/miniconda3/lib/python3.7/smtplib.py", line 730, in login
    raise last_exception
  File "/home/weiss/miniconda3/lib/python3.7/smtplib.py", line 721, in login
    initial_response_ok=initial_response_ok)
  File "/home/weiss/miniconda3/lib/python3.7/smtplib.py", line 642, in auth
    raise SMTPAuthenticationError(code, resp)
smtplib.SMTPAuthenticationError: (534, b'5.7.9 Application-specific password required. Learn more at\n5.7.9  https://support.google.com/mail/?p=InvalidSecondFactor k9sm66934646wru.55 - gsmtp')
2019-04-14 12:37:44,873 ERROR: Internal error, please wait until the maintainers fix the issue [in /home/weiss/CODES/BM/intent_gatherer/flask_backend/app/errors.py:13]
2019-04-14 12:38:00,837 ERROR: Exception on /reset_pass [POST] [in /home/weiss/CODES/BM/intent_gatherer/intent_gatherer_venv/lib/python3.7/site-packages/flask/app.py:1761]
Traceback (most recent call last):
  File "/home/weiss/CODES/BM/intent_gatherer/intent_gatherer_venv/lib/python3.7/site-packages/flask/app.py", line 2292, in wsgi_app
    response = self.full_dispatch_request()
  File "/home/weiss/CODES/BM/intent_gatherer/intent_gatherer_venv/lib/python3.7/site-packages/flask/app.py", line 1815, in full_dispatch_request
    rv = self.handle_user_exception(e)
  File "/home/weiss/CODES/BM/intent_gatherer/intent_gatherer_venv/lib/python3.7/site-packages/flask/app.py", line 1718, in handle_user_exception
    reraise(exc_type, exc_value, tb)
  File "/home/weiss/CODES/BM/intent_gatherer/intent_gatherer_venv/lib/python3.7/site-packages/flask/_compat.py", line 35, in reraise
    raise value
  File "/home/weiss/CODES/BM/intent_gatherer/intent_gatherer_venv/lib/python3.7/site-packages/flask/app.py", line 1813, in full_dispatch_request
    rv = self.dispatch_request()
  File "/home/weiss/CODES/BM/intent_gatherer/intent_gatherer_venv/lib/python3.7/site-packages/flask/app.py", line 1799, in dispatch_request
    return self.view_functions[rule.endpoint](**req.view_args)
  File "/home/weiss/CODES/BM/intent_gatherer/flask_backend/app/routes.py", line 145, in reset_password
    send_password_reset_email(user)
  File "/home/weiss/CODES/BM/intent_gatherer/flask_backend/app/email.py", line 17, in send_password_reset_email
    text_body=render_template('reset_pass_mail_text.txt',user=user,token=token))
  File "/home/weiss/CODES/BM/intent_gatherer/flask_backend/app/email.py", line 8, in send_mail
    mail.send(message)
  File "/home/weiss/CODES/BM/intent_gatherer/intent_gatherer_venv/lib/python3.7/site-packages/flask_mail.py", line 491, in send
    with self.connect() as connection:
  File "/home/weiss/CODES/BM/intent_gatherer/intent_gatherer_venv/lib/python3.7/site-packages/flask_mail.py", line 144, in __enter__
    self.host = self.configure_host()
  File "/home/weiss/CODES/BM/intent_gatherer/intent_gatherer_venv/lib/python3.7/site-packages/flask_mail.py", line 165, in configure_host
    host.login(self.mail.username, self.mail.password)
  File "/home/weiss/miniconda3/lib/python3.7/smtplib.py", line 730, in login
    raise last_exception
  File "/home/weiss/miniconda3/lib/python3.7/smtplib.py", line 721, in login
    initial_response_ok=initial_response_ok)
  File "/home/weiss/miniconda3/lib/python3.7/smtplib.py", line 642, in auth
    raise SMTPAuthenticationError(code, resp)
smtplib.SMTPAuthenticationError: (534, b'5.7.9 Application-specific password required. Learn more at\n5.7.9  https://support.google.com/mail/?p=InvalidSecondFactor c16sm16972485wme.31 - gsmtp')
2019-04-14 12:38:00,838 ERROR: Internal error, please wait until the maintainers fix the issue [in /home/weiss/CODES/BM/intent_gatherer/flask_backend/app/errors.py:13]
2019-04-14 12:38:06,743 INFO: The application started [in /home/weiss/CODES/BM/intent_gatherer/flask_backend/app/__init__.py:44]
